The above exception was the direct cause of the following exception:

Traceback (most recent call last):
  File "/home/ubuntu/miniconda3/lib/python3.12/site-packages/qiskit_ibm_runtime/api/rest/runtime_session.py", line 77, in close
    self.session.patch(url, json=payload)
  File "/home/ubuntu/miniconda3/lib/python3.12/site-packages/requests/sessions.py", line 661, in patch
    return self.request("PATCH", url, data=data, **kwargs)
           ^^^^^^^^^^^^^^^^^^^^^^^^^^^^^^^^^^^^^^^^^^^^^^^
  File "/home/ubuntu/miniconda3/lib/python3.12/site-packages/qiskit_ibm_runtime/api/session.py", line 351, in request
    raise RequestsApiError(message, status_code) from ex
qiskit_ibm_runtime.api.exceptions.RequestsApiError: 'HTTPSConnectionPool(host=\'api.quantum.ibm.com\', port=443): Max retries exceeded with url: /runtime/sessions/cxy4hvf3wrp0008m1n20 (Caused by NameResolutionError("<urllib3.connection.HTTPSConnection object at 0x7f583d448290>: Failed to resolve \'api.quantum.ibm.com\' ([Errno -5] No address associated with hostname)"))'

During handling of the above exception, another exception occurred:

Traceback (most recent call last):
  File "/home/ubuntu/Pennylane_to_Qiskit/convert_ML.py", line 401, in <module>
    with Session(backend=_backend) as session:
         ^^^^^^^^^^^^^^^^^^^^^^^^^
  File "/home/ubuntu/miniconda3/lib/python3.12/site-packages/qiskit_ibm_runtime/session.py", line 399, in __exit__
    self.close()
  File "/home/ubuntu/miniconda3/lib/python3.12/site-packages/qiskit_ibm_runtime/session.py", line 252, in close
    self._service._api_client.close_session(self._session_id)
  File "/home/ubuntu/miniconda3/lib/python3.12/site-packages/qiskit_ibm_runtime/api/clients/runtime.py", line 264, in close_session
    self._api.runtime_session(session_id=session_id).close()
  File "/home/ubuntu/miniconda3/lib/python3.12/site-packages/qiskit_ibm_runtime/api/rest/runtime_session.py", line 82, in close
    raise IBMRuntimeError(f"Error closing session: {ex}")
qiskit_ibm_runtime.exceptions.IBMRuntimeError: 'Error closing session: \'HTTPSConnectionPool(host=\\\'api.quantum.ibm.com\\\', port=443): Max retries exceeded with url: /runtime/sessions/cxy4hvf3wrp0008m1n20 (Caused by NameResolutionError("<urllib3.connection.HTTPSConnection object at 0x7f583d448290>: Failed to resolve \\\'api.quantum.ibm.com\\\' ([Errno -5] No address associated with hostname)"))\''
